<?xml version="1.0"?>
<robot name="butler_robot" xmlns:xacro="http://www.ros.org/wiki/xacro">

    <!-- Base Link -->
    <link name="base_link">
        <visual>
            <geometry>
                <box size="0.5 0.5 0.2"/>
            </geometry>
            <material name="Gray">
                <color rgba="0.5 0.5 0.5 1"/>
            </material>
        </visual>
        <collision>
            <geometry>
                <box size="0.5 0.5 0.2"/>
            </geometry>
        </collision>
        <inertial>
            <mass value="1.0"/>
            <origin xyz="0 0 0"/>
            <inertia ixx="0.02" ixy="0" ixz="0" iyy="0.02" iyz="0" izz="0.02"/>
        </inertial>
    </link>

    <!-- Left Wheel -->
    <link name="left_wheel">
        <visual>
            <geometry>
                <cylinder length="0.02" radius="0.1"/>
            </geometry>
            <material name="Black">
                <color rgba="0.0 0.0 0.0 1"/>
            </material>
        </visual>
        <collision>
            <geometry>
                <cylinder length="0.02" radius="0.1"/>
            </geometry>
        </collision>
        <inertial>
            <mass value="0.2"/>
            <origin xyz="0 0 0"/>
            <inertia ixx="0.005" ixy="0" ixz="0" iyy="0.005" iyz="0" izz="0.005"/>
        </inertial>
    </link>

    <!-- Right Wheel -->
    <link name="right_wheel">
        <visual>
            <geometry>
                <cylinder length="0.02" radius="0.1"/>
            </geometry>
            <material name="Black">
                <color rgba="0.0 0.0 0.0 1"/>
            </material>
        </visual>
        <collision>
            <geometry>
                <cylinder length="0.02" radius="0.1"/>
            </geometry>
        </collision>
        <inertial>
            <mass value="0.2"/>
            <origin xyz="0 0 0"/>
            <inertia ixx="0.005" ixy="0" ixz="0" iyy="0.005" iyz="0" izz="0.005"/>
        </inertial>
    </link>

    <!-- Joints -->
    <joint name="left_wheel_joint" type="continuous">
        <parent link="base_link"/>
        <child link="left_wheel"/>
        <origin xyz="0.0 0.2 -0.1"/>
        <axis xyz="0 1 0"/>
        <limit effort="1.0" velocity="10.0"/>
    </joint>

    <joint name="right_wheel_joint" type="continuous">
        <parent link="base_link"/>
        <child link="right_wheel"/>
        <origin xyz="0.0 -0.2 -0.1"/>
        <axis xyz="0 1 0"/>
        <limit effort="1.0" velocity="10.0"/>
    </joint>

    <!-- Gazebo Plugin for Diff Drive -->
    <gazebo reference="base_link">
        <plugin name="diff_drive_controller" filename="libgazebo_ros_diff_drive.so">
            <robotNamespace>/</robotNamespace>
            <commandTopic>cmd_vel</commandTopic>
            <odometryTopic>odom</odometryTopic>
            <odometryFrame>odom</odometryFrame>
            <robotBaseFrame>base_link</robotBaseFrame>
            <publishWheelTF>true</publishWheelTF>
            <publishOdomTF>true</publishOdomTF>
            <publishWheelJointState>true</publishWheelJointState>
            <leftJoint>left_wheel_joint</leftJoint>
            <rightJoint>right_wheel_joint</rightJoint>
            <wheelSeparation>0.34</wheelSeparation>
            <wheelDiameter>0.15</wheelDiameter>
            <wheelTorque>5.0</wheelTorque>
            <updateRate>100.0</updateRate>
            <odometrySource>1</odometrySource>
        </plugin>
    </gazebo>

</robot>
